Traceback (most recent call last):
  File "gviz.pyc", line 145, in resize
ZeroDivisionError: float division
Traceback (most recent call last):
  File "gviz.pyc", line 145, in resize
ZeroDivisionError: float division
Traceback (most recent call last):
  File "gviz.pyc", line 145, in resize
ZeroDivisionError: float division
Traceback (most recent call last):
  File "gviz.pyc", line 145, in resize
ZeroDivisionError: float division
Traceback (most recent call last):
  File "gviz.pyc", line 145, in resize
ZeroDivisionError: float division
Traceback (most recent call last):
  File "gviz.pyc", line 145, in resize
ZeroDivisionError: float division
Traceback (most recent call last):
  File "gviz.pyc", line 145, in resize
ZeroDivisionError: float division
Traceback (most recent call last):
  File "gviz.pyc", line 145, in resize
ZeroDivisionError: float division
Traceback (most recent call last):
  File "gviz.pyc", line 145, in resize
ZeroDivisionError: float division
Traceback (most recent call last):
  File "gviz.pyc", line 145, in resize
ZeroDivisionError: float division
Traceback (most recent call last):
  File "gviz.pyc", line 145, in resize
ZeroDivisionError: float division
Traceback (most recent call last):
  File "gviz.pyc", line 145, in resize
ZeroDivisionError: float division
Traceback (most recent call last):
  File "gviz.pyc", line 145, in resize
ZeroDivisionError: float division
Traceback (most recent call last):
  File "gviz.pyc", line 145, in resize
ZeroDivisionError: float division
Traceback (most recent call last):
  File "gviz.pyc", line 145, in resize
ZeroDivisionError: float division
Traceback (most recent call last):
  File "gviz.pyc", line 145, in resize
ZeroDivisionError: float division
Traceback (most recent call last):
  File "gviz.pyc", line 145, in resize
ZeroDivisionError: float division
Traceback (most recent call last):
  File "gviz.pyc", line 145, in resize
ZeroDivisionError: float division
Traceback (most recent call last):
  File "gviz.pyc", line 145, in resize
ZeroDivisionError: float division
Traceback (most recent call last):
  File "gviz.pyc", line 145, in resize
ZeroDivisionError: float division
Traceback (most recent call last):
  File "gviz.pyc", line 145, in resize
ZeroDivisionError: float division
Traceback (most recent call last):
  File "gviz.pyc", line 145, in resize
ZeroDivisionError: float division
Traceback (most recent call last):
  File "gviz.pyc", line 145, in resize
ZeroDivisionError: float division
Traceback (most recent call last):
  File "gviz.pyc", line 145, in resize
ZeroDivisionError: float division
Traceback (most recent call last):
  File "gviz.pyc", line 145, in resize
ZeroDivisionError: float division
Traceback (most recent call last):
  File "gviz.pyc", line 145, in resize
ZeroDivisionError: float division
Traceback (most recent call last):
  File "gviz.pyc", line 145, in resize
ZeroDivisionError: float division
Traceback (most recent call last):
  File "gviz.pyc", line 145, in resize
ZeroDivisionError: float division
Traceback (most recent call last):
  File "gviz.pyc", line 145, in resize
ZeroDivisionError: float division
Traceback (most recent call last):
  File "gviz.pyc", line 145, in resize
ZeroDivisionError: float division
Traceback (most recent call last):
  File "gviz.pyc", line 145, in resize
ZeroDivisionError: float division
Traceback (most recent call last):
  File "gviz.pyc", line 145, in resize
ZeroDivisionError: float division
Traceback (most recent call last):
  File "gviz.pyc", line 145, in resize
ZeroDivisionError: float division
Traceback (most recent call last):
  File "gviz.pyc", line 145, in resize
ZeroDivisionError: float division
Traceback (most recent call last):
  File "gviz.pyc", line 145, in resize
ZeroDivisionError: float division
Traceback (most recent call last):
  File "gviz.pyc", line 145, in resize
ZeroDivisionError: float division
Traceback (most recent call last):
  File "gviz.pyc", line 145, in resize
ZeroDivisionError: float division
Traceback (most recent call last):
  File "gviz.pyc", line 145, in resize
ZeroDivisionError: float division
Traceback (most recent call last):
  File "gviz.pyc", line 145, in resize
ZeroDivisionError: float division
Traceback (most recent call last):
  File "gviz.pyc", line 145, in resize
ZeroDivisionError: float division
Traceback (most recent call last):
  File "gviz.pyc", line 145, in resize
ZeroDivisionError: float division
Traceback (most recent call last):
  File "gviz.pyc", line 145, in resize
ZeroDivisionError: float division
Traceback (most recent call last):
  File "gviz.pyc", line 145, in resize
ZeroDivisionError: float division
Traceback (most recent call last):
  File "gviz.pyc", line 145, in resize
ZeroDivisionError: float division
Traceback (most recent call last):
  File "gviz.pyc", line 145, in resize
ZeroDivisionError: float division
Traceback (most recent call last):
  File "gviz.pyc", line 145, in resize
ZeroDivisionError: float division
Traceback (most recent call last):
  File "gviz.pyc", line 145, in resize
ZeroDivisionError: float division
Traceback (most recent call last):
  File "gviz.pyc", line 145, in resize
ZeroDivisionError: float division
Traceback (most recent call last):
  File "gviz.pyc", line 145, in resize
ZeroDivisionError: float division
Traceback (most recent call last):
  File "gviz.pyc", line 145, in resize
ZeroDivisionError: float division
Traceback (most recent call last):
  File "gviz.pyc", line 145, in resize
ZeroDivisionError: float division
Traceback (most recent call last):
  File "gviz.pyc", line 145, in resize
ZeroDivisionError: float division
Traceback (most recent call last):
  File "gviz.pyc", line 145, in resize
ZeroDivisionError: float division
Traceback (most recent call last):
  File "gviz.pyc", line 145, in resize
ZeroDivisionError: float division
Traceback (most recent call last):
  File "gviz.pyc", line 145, in resize
ZeroDivisionError: float division
Traceback (most recent call last):
  File "gviz.pyc", line 145, in resize
ZeroDivisionError: float division
Traceback (most recent call last):
  File "gviz.pyc", line 145, in resize
ZeroDivisionError: float division
Traceback (most recent call last):
  File "gviz.pyc", line 145, in resize
ZeroDivisionError: float division
Traceback (most recent call last):
  File "gviz.pyc", line 145, in resize
ZeroDivisionError: float division
Traceback (most recent call last):
  File "gviz.pyc", line 145, in resize
ZeroDivisionError: float division
Traceback (most recent call last):
  File "gviz.pyc", line 145, in resize
ZeroDivisionError: float division
Traceback (most recent call last):
  File "gviz.pyc", line 145, in resize
ZeroDivisionError: float division
Traceback (most recent call last):
  File "gviz.pyc", line 145, in resize
ZeroDivisionError: float division
Traceback (most recent call last):
  File "gviz.pyc", line 145, in resize
ZeroDivisionError: float division
Traceback (most recent call last):
  File "gviz.pyc", line 145, in resize
ZeroDivisionError: float division
Traceback (most recent call last):
  File "gviz.pyc", line 145, in resize
ZeroDivisionError: float division
Traceback (most recent call last):
  File "gviz.pyc", line 145, in resize
ZeroDivisionError: float division
Traceback (most recent call last):
  File "gviz.pyc", line 145, in resize
ZeroDivisionError: float division
Traceback (most recent call last):
  File "gviz.pyc", line 145, in resize
ZeroDivisionError: float division
Traceback (most recent call last):
  File "gviz.pyc", line 145, in resize
ZeroDivisionError: float division
Traceback (most recent call last):
  File "gviz.pyc", line 145, in resize
ZeroDivisionError: float division
Exception AttributeError: "'NoneType' object has no attribute 'stdout'" in <bound method Tee.__del__ of <__main__.Tee object at 0x03D76FB0>> ignored
Exception AttributeError: "'NoneType' object has no attribute 'stdout'" in <bound method Tee.__del__ of <__main__.Tee object at 0x03D440F0>> ignored
Traceback (most recent call last):
  File "pronterface.py", line 1566, in connect
  File "printcore.pyc", line 76, in connect
  File "serial\serialwin32.pyc", line 30, in __init__
  File "serial\serialutil.pyc", line 260, in __init__
  File "serial\serialwin32.pyc", line 56, in open
serial.serialutil.SerialException: could not open port COM3: [Error 2] The system cannot find the file specified.
Exception in thread Thread-1:
Traceback (most recent call last):
  File "threading.pyc", line 532, in __bootstrap_inner
  File "threading.pyc", line 484, in run
  File "printcore.pyc", line 97, in _listen
  File "io.pyc", line 520, in readline
  File "serial\serialwin32.pyc", line 212, in read
ValueError: Attempting to use a port that is not open

Traceback (most recent call last):
  File "pronterface.py", line 1566, in connect
  File "printcore.pyc", line 76, in connect
  File "serial\serialwin32.pyc", line 30, in __init__
  File "serial\serialutil.pyc", line 260, in __init__
  File "serial\serialwin32.pyc", line 56, in open
serial.serialutil.SerialException: could not open port COM1: [Error 5] Access is denied.
Traceback (most recent call last):
  File "pronterface.py", line 1566, in connect
  File "printcore.pyc", line 76, in connect
  File "serial\serialwin32.pyc", line 30, in __init__
  File "serial\serialutil.pyc", line 260, in __init__
  File "serial\serialwin32.pyc", line 56, in open
serial.serialutil.SerialException: could not open port COM1: [Error 5] Access is denied.
Traceback (most recent call last):
  File "pronterface.py", line 1566, in connect
  File "printcore.pyc", line 76, in connect
  File "serial\serialwin32.pyc", line 30, in __init__
  File "serial\serialutil.pyc", line 260, in __init__
  File "serial\serialwin32.pyc", line 56, in open
serial.serialutil.SerialException: could not open port COM1: [Error 5] Access is denied.
Traceback (most recent call last):
  File "pronterface.py", line 1566, in connect
  File "printcore.pyc", line 76, in connect
  File "serial\serialwin32.pyc", line 30, in __init__
  File "serial\serialutil.pyc", line 260, in __init__
  File "serial\serialwin32.pyc", line 56, in open
serial.serialutil.SerialException: could not open port COM3: [Error 2] The system cannot find the file specified.
Traceback (most recent call last):
  File "pronterface.py", line 1566, in connect
  File "printcore.pyc", line 76, in connect
  File "serial\serialwin32.pyc", line 30, in __init__
  File "serial\serialutil.pyc", line 260, in __init__
  File "serial\serialwin32.pyc", line 56, in open
serial.serialutil.SerialException: could not open port COM1: [Error 5] Access is denied.
Traceback (most recent call last):
  File "pronterface.py", line 1566, in connect
  File "printcore.pyc", line 76, in connect
  File "serial\serialwin32.pyc", line 30, in __init__
  File "serial\serialutil.pyc", line 260, in __init__
  File "serial\serialwin32.pyc", line 56, in open
serial.serialutil.SerialException: could not open port COM3: [Error 2] The system cannot find the file specified.
Traceback (most recent call last):
  File "pronterface.py", line 1566, in connect
  File "printcore.pyc", line 76, in connect
  File "serial\serialwin32.pyc", line 30, in __init__
  File "serial\serialutil.pyc", line 260, in __init__
  File "serial\serialwin32.pyc", line 56, in open
serial.serialutil.SerialException: could not open port COM40: [Error 2] The system cannot find the file specified.
Traceback (most recent call last):
  File "pronterface.py", line 1566, in connect
  File "printcore.pyc", line 76, in connect
  File "serial\serialwin32.pyc", line 30, in __init__
  File "serial\serialutil.pyc", line 260, in __init__
  File "serial\serialwin32.pyc", line 56, in open
serial.serialutil.SerialException: could not open port COM40: [Error 2] The system cannot find the file specified.
Traceback (most recent call last):
  File "pronterface.py", line 1566, in connect
  File "printcore.pyc", line 76, in connect
  File "serial\serialwin32.pyc", line 30, in __init__
  File "serial\serialutil.pyc", line 260, in __init__
  File "serial\serialwin32.pyc", line 56, in open
serial.serialutil.SerialException: could not open port COM40: [Error 2] The system cannot find the file specified.
Traceback (most recent call last):
  File "wx\_core.pyc", line 14669, in <lambda>
  File "wx\_core.pyc", line 9771, in Refresh
TypeError: in method 'Window_Refresh', expected argument 1 of type 'wxWindow *'
Exception AttributeError: "'NoneType' object has no attribute 'stdout'" in <bound method Tee.__del__ of <__main__.Tee object at 0x03E84FD0>> ignored
Traceback (most recent call last):
  File "wx\_core.pyc", line 14669, in <lambda>
  File "wx\_controls.pyc", line 1850, in AppendText
  File "encodings\cp1252.pyc", line 15, in decode
UnicodeDecodeError: 'charmap' codec can't decode byte 0x90 in position 41: character maps to <undefined>
Traceback (most recent call last):
  File "pronterface.py", line 1566, in connect
  File "printcore.pyc", line 76, in connect
  File "serial\serialwin32.pyc", line 30, in __init__
  File "serial\serialutil.pyc", line 260, in __init__
  File "serial\serialwin32.pyc", line 56, in open
serial.serialutil.SerialException: could not open port COM40: [Error 5] Access is denied.
Traceback (most recent call last):
  File "pronterface.py", line 1566, in connect
  File "printcore.pyc", line 76, in connect
  File "serial\serialwin32.pyc", line 30, in __init__
  File "serial\serialutil.pyc", line 260, in __init__
  File "serial\serialwin32.pyc", line 56, in open
serial.serialutil.SerialException: could not open port COM40: [Error 2] The system cannot find the file specified.
Traceback (most recent call last):
  File "pronterface.py", line 1566, in connect
  File "printcore.pyc", line 76, in connect
  File "serial\serialwin32.pyc", line 30, in __init__
  File "serial\serialutil.pyc", line 260, in __init__
  File "serial\serialwin32.pyc", line 56, in open
serial.serialutil.SerialException: could not open port COM40: [Error 2] The system cannot find the file specified.
Traceback (most recent call last):
  File "pronterface.py", line 1566, in connect
  File "printcore.pyc", line 76, in connect
  File "serial\serialwin32.pyc", line 30, in __init__
  File "serial\serialutil.pyc", line 260, in __init__
  File "serial\serialwin32.pyc", line 56, in open
serial.serialutil.SerialException: could not open port COM40: [Error 2] The system cannot find the file specified.
Traceback (most recent call last):
  File "pronterface.py", line 1566, in connect
  File "printcore.pyc", line 76, in connect
  File "serial\serialwin32.pyc", line 30, in __init__
  File "serial\serialutil.pyc", line 260, in __init__
  File "serial\serialwin32.pyc", line 56, in open
serial.serialutil.SerialException: could not open port COM40: [Error 2] The system cannot find the file specified.
Traceback (most recent call last):
  File "pronterface.py", line 1566, in connect
  File "printcore.pyc", line 76, in connect
  File "serial\serialwin32.pyc", line 30, in __init__
  File "serial\serialutil.pyc", line 260, in __init__
  File "serial\serialwin32.pyc", line 56, in open
serial.serialutil.SerialException: could not open port COM40: [Error 2] The system cannot find the file specified.
Traceback (most recent call last):
  File "pronterface.py", line 1566, in connect
  File "printcore.pyc", line 76, in connect
  File "serial\serialwin32.pyc", line 30, in __init__
  File "serial\serialutil.pyc", line 260, in __init__
  File "serial\serialwin32.pyc", line 56, in open
serial.serialutil.SerialException: could not open port COM40: [Error 2] The system cannot find the file specified.
Traceback (most recent call last):
  File "pronterface.py", line 1566, in connect
  File "printcore.pyc", line 76, in connect
  File "serial\serialwin32.pyc", line 30, in __init__
  File "serial\serialutil.pyc", line 260, in __init__
  File "serial\serialwin32.pyc", line 56, in open
serial.serialutil.SerialException: could not open port COM40: [Error 2] The system cannot find the file specified.
Traceback (most recent call last):
  File "pronterface.py", line 1566, in connect
  File "printcore.pyc", line 76, in connect
  File "serial\serialwin32.pyc", line 30, in __init__
  File "serial\serialutil.pyc", line 260, in __init__
  File "serial\serialwin32.pyc", line 56, in open
serial.serialutil.SerialException: could not open port COM40: [Error 2] The system cannot find the file specified.
Traceback (most recent call last):
  File "pronterface.py", line 1566, in connect
  File "printcore.pyc", line 76, in connect
  File "serial\serialwin32.pyc", line 30, in __init__
  File "serial\serialutil.pyc", line 260, in __init__
  File "serial\serialwin32.pyc", line 56, in open
serial.serialutil.SerialException: could not open port COM40: [Error 2] The system cannot find the file specified.
Traceback (most recent call last):
  File "pronterface.py", line 1566, in connect
  File "printcore.pyc", line 76, in connect
  File "serial\serialwin32.pyc", line 30, in __init__
  File "serial\serialutil.pyc", line 260, in __init__
  File "serial\serialwin32.pyc", line 56, in open
serial.serialutil.SerialException: could not open port COM40: [Error 2] The system cannot find the file specified.
Traceback (most recent call last):
  File "pronterface.py", line 1566, in connect
  File "printcore.pyc", line 76, in connect
  File "serial\serialwin32.pyc", line 30, in __init__
  File "serial\serialutil.pyc", line 260, in __init__
  File "serial\serialwin32.pyc", line 56, in open
serial.serialutil.SerialException: could not open port COM40: [Error 2] The system cannot find the file specified.
Traceback (most recent call last):
  File "pronterface.py", line 1566, in connect
  File "printcore.pyc", line 76, in connect
  File "serial\serialwin32.pyc", line 30, in __init__
  File "serial\serialutil.pyc", line 260, in __init__
  File "serial\serialwin32.pyc", line 56, in open
serial.serialutil.SerialException: could not open port COM40: [Error 2] The system cannot find the file specified.
Traceback (most recent call last):
  File "pronterface.py", line 1566, in connect
  File "printcore.pyc", line 76, in connect
  File "serial\serialwin32.pyc", line 30, in __init__
  File "serial\serialutil.pyc", line 260, in __init__
  File "serial\serialwin32.pyc", line 56, in open
serial.serialutil.SerialException: could not open port COM40: [Error 2] The system cannot find the file specified.
Traceback (most recent call last):
  File "pronterface.py", line 1566, in connect
  File "printcore.pyc", line 76, in connect
  File "serial\serialwin32.pyc", line 30, in __init__
  File "serial\serialutil.pyc", line 260, in __init__
  File "serial\serialwin32.pyc", line 56, in open
serial.serialutil.SerialException: could not open port COM40: [Error 2] The system cannot find the file specified.
Traceback (most recent call last):
  File "pronterface.py", line 1566, in connect
  File "printcore.pyc", line 76, in connect
  File "serial\serialwin32.pyc", line 30, in __init__
  File "serial\serialutil.pyc", line 260, in __init__
  File "serial\serialwin32.pyc", line 56, in open
serial.serialutil.SerialException: could not open port COM40: [Error 2] The system cannot find the file specified.
Traceback (most recent call last):
  File "pronterface.py", line 1566, in connect
  File "printcore.pyc", line 76, in connect
  File "serial\serialwin32.pyc", line 30, in __init__
  File "serial\serialutil.pyc", line 260, in __init__
  File "serial\serialwin32.pyc", line 56, in open
serial.serialutil.SerialException: could not open port COM40: [Error 2] The system cannot find the file specified.
Traceback (most recent call last):
  File "pronterface.py", line 1566, in connect
  File "printcore.pyc", line 76, in connect
  File "serial\serialwin32.pyc", line 30, in __init__
  File "serial\serialutil.pyc", line 260, in __init__
  File "serial\serialwin32.pyc", line 56, in open
serial.serialutil.SerialException: could not open port COM40: [Error 2] The system cannot find the file specified.
Traceback (most recent call last):
  File "pronterface.py", line 1566, in connect
  File "printcore.pyc", line 76, in connect
  File "serial\serialwin32.pyc", line 30, in __init__
  File "serial\serialutil.pyc", line 260, in __init__
  File "serial\serialwin32.pyc", line 56, in open
serial.serialutil.SerialException: could not open port COM40: [Error 2] The system cannot find the file specified.
Exception in thread Thread-10:
Traceback (most recent call last):
  File "threading.pyc", line 532, in __bootstrap_inner
  File "threading.pyc", line 484, in run
  File "pronterface.py", line 1451, in loadviz
  File "pronsole.pyc", line 147, in estimate_duration
  File "pronsole.pyc", line 109, in get_coordinate_value
ValueError: invalid literal for float(): 177	F10000

Traceback (most recent call last):
  File "pronterface.py", line 1566, in connect
  File "printcore.pyc", line 76, in connect
  File "serial\serialwin32.pyc", line 30, in __init__
  File "serial\serialutil.pyc", line 260, in __init__
  File "serial\serialwin32.pyc", line 56, in open
serial.serialutil.SerialException: could not open port COM40: [Error 2] The system cannot find the file specified.
Traceback (most recent call last):
  File "pronterface.py", line 1566, in connect
  File "printcore.pyc", line 76, in connect
  File "serial\serialwin32.pyc", line 30, in __init__
  File "serial\serialutil.pyc", line 260, in __init__
  File "serial\serialwin32.pyc", line 56, in open
serial.serialutil.SerialException: could not open port COM40: [Error 2] The system cannot find the file specified.
Traceback (most recent call last):
  File "pronterface.py", line 1566, in connect
  File "printcore.pyc", line 76, in connect
  File "serial\serialwin32.pyc", line 30, in __init__
  File "serial\serialutil.pyc", line 260, in __init__
  File "serial\serialwin32.pyc", line 56, in open
serial.serialutil.SerialException: could not open port COM40: [Error 2] The system cannot find the file specified.
Traceback (most recent call last):
  File "pronterface.py", line 1566, in connect
  File "printcore.pyc", line 76, in connect
  File "serial\serialwin32.pyc", line 30, in __init__
  File "serial\serialutil.pyc", line 260, in __init__
  File "serial\serialwin32.pyc", line 56, in open
serial.serialutil.SerialException: could not open port COM40: [Error 2] The system cannot find the file specified.
Traceback (most recent call last):
  File "pronterface.py", line 1566, in connect
  File "printcore.pyc", line 76, in connect
  File "serial\serialwin32.pyc", line 30, in __init__
  File "serial\serialutil.pyc", line 260, in __init__
  File "serial\serialwin32.pyc", line 56, in open
serial.serialutil.SerialException: could not open port COM40: [Error 2] The system cannot find the file specified.
Traceback (most recent call last):
  File "pronterface.py", line 1566, in connect
  File "printcore.pyc", line 76, in connect
  File "serial\serialwin32.pyc", line 30, in __init__
  File "serial\serialutil.pyc", line 260, in __init__
  File "serial\serialwin32.pyc", line 56, in open
serial.serialutil.SerialException: could not open port COM40: [Error 2] The system cannot find the file specified.
Traceback (most recent call last):
  File "pronterface.py", line 1566, in connect
  File "printcore.pyc", line 76, in connect
  File "serial\serialwin32.pyc", line 30, in __init__
  File "serial\serialutil.pyc", line 260, in __init__
  File "serial\serialwin32.pyc", line 56, in open
serial.serialutil.SerialException: could not open port COM40: [Error 2] The system cannot find the file specified.
Traceback (most recent call last):
  File "pronterface.py", line 1566, in connect
  File "printcore.pyc", line 76, in connect
  File "serial\serialwin32.pyc", line 30, in __init__
  File "serial\serialutil.pyc", line 260, in __init__
  File "serial\serialwin32.pyc", line 56, in open
serial.serialutil.SerialException: could not open port COM40: [Error 2] The system cannot find the file specified.
Traceback (most recent call last):
  File "pronterface.py", line 1566, in connect
  File "printcore.pyc", line 76, in connect
  File "serial\serialwin32.pyc", line 30, in __init__
  File "serial\serialutil.pyc", line 260, in __init__
  File "serial\serialwin32.pyc", line 68, in open
  File "serial\serialwin32.pyc", line 177, in _reconfigurePort
ValueError: Cannot configure port, some setting was wrong. Original message: [Error 31] A device attached to the system is not functioning.
Traceback (most recent call last):
  File "pronterface.py", line 1566, in connect
  File "printcore.pyc", line 76, in connect
  File "serial\serialwin32.pyc", line 30, in __init__
  File "serial\serialutil.pyc", line 260, in __init__
  File "serial\serialwin32.pyc", line 56, in open
serial.serialutil.SerialException: could not open port COM40: [Error 5] Access is denied.
Traceback (most recent call last):
  File "pronterface.py", line 1566, in connect
  File "printcore.pyc", line 76, in connect
  File "serial\serialwin32.pyc", line 30, in __init__
  File "serial\serialutil.pyc", line 260, in __init__
  File "serial\serialwin32.pyc", line 56, in open
serial.serialutil.SerialException: could not open port COM40: [Error 2] The system cannot find the file specified.
Traceback (most recent call last):
  File "pronterface.py", line 1566, in connect
  File "printcore.pyc", line 76, in connect
  File "serial\serialwin32.pyc", line 30, in __init__
  File "serial\serialutil.pyc", line 260, in __init__
  File "serial\serialwin32.pyc", line 56, in open
serial.serialutil.SerialException: could not open port COM40: [Error 2] The system cannot find the file specified.
Traceback (most recent call last):
  File "pronterface.py", line 1566, in connect
  File "printcore.pyc", line 76, in connect
  File "serial\serialwin32.pyc", line 30, in __init__
  File "serial\serialutil.pyc", line 260, in __init__
  File "serial\serialwin32.pyc", line 56, in open
serial.serialutil.SerialException: could not open port COM40: [Error 2] The system cannot find the file specified.
Traceback (most recent call last):
  File "pronterface.py", line 1566, in connect
  File "printcore.pyc", line 76, in connect
  File "serial\serialwin32.pyc", line 30, in __init__
  File "serial\serialutil.pyc", line 260, in __init__
  File "serial\serialwin32.pyc", line 56, in open
serial.serialutil.SerialException: could not open port COM40: [Error 2] The system cannot find the file specified.
